Wed Oct 16 13:12:23 EEST 2024 Thread[#41,Thread-2,5,main] Cleanup action starting
java.sql.SQLException: Database 'D:/RealDBAPI' not found.
	at org.apache.derby.impl.jdbc.SQLExceptionFactory.getSQLException(SQLExceptionFactory.java:115)
	at org.apache.derby.impl.jdbc.SQLExceptionFactory.getSQLException(SQLExceptionFactory.java:141)
	at org.apache.derby.impl.jdbc.Util.generateCsSQLException(Util.java:225)
	at org.apache.derby.impl.jdbc.Util.generateCsSQLException(Util.java:220)
	at org.apache.derby.impl.jdbc.EmbedConnection.newSQLException(EmbedConnection.java:3208)
	at org.apache.derby.impl.jdbc.EmbedConnection.handleDBNotFound(EmbedConnection.java:767)
	at org.apache.derby.impl.jdbc.EmbedConnection.<init>(EmbedConnection.java:437)
	at org.apache.derby.iapi.jdbc.InternalDriver.getNewEmbedConnection(InternalDriver.java:630)
	at org.apache.derby.iapi.jdbc.InternalDriver$LoginCallable.call(InternalDriver.java:400)
	at org.apache.derby.iapi.jdbc.InternalDriver$LoginCallable.call(InternalDriver.java:376)
	at java.base/java.util.concurrent.FutureTask.run(FutureTask.java:317)
	at java.base/java.util.concurrent.ThreadPoolExecutor.runWorker(ThreadPoolExecutor.java:1144)
	at java.base/java.util.concurrent.ThreadPoolExecutor$Worker.run(ThreadPoolExecutor.java:642)
	at java.base/java.lang.Thread.run(Thread.java:1583)
Caused by: ERROR XJ004: Database 'D:/RealDBAPI' not found.
	at org.apache.derby.shared.common.error.StandardException.newException(StandardException.java:299)
	at org.apache.derby.impl.jdbc.SQLExceptionFactory.wrapArgsForTransportAcrossDRDA(SQLExceptionFactory.java:170)
	at org.apache.derby.impl.jdbc.SQLExceptionFactory.getSQLException(SQLExceptionFactory.java:75)
	... 13 more
============= begin nested exception, level (1) ===========
ERROR XJ004: Database 'D:/RealDBAPI' not found.
	at org.apache.derby.shared.common.error.StandardException.newException(StandardException.java:299)
	at org.apache.derby.impl.jdbc.SQLExceptionFactory.wrapArgsForTransportAcrossDRDA(SQLExceptionFactory.java:170)
	at org.apache.derby.impl.jdbc.SQLExceptionFactory.getSQLException(SQLExceptionFactory.java:75)
	at org.apache.derby.impl.jdbc.SQLExceptionFactory.getSQLException(SQLExceptionFactory.java:141)
	at org.apache.derby.impl.jdbc.Util.generateCsSQLException(Util.java:225)
	at org.apache.derby.impl.jdbc.Util.generateCsSQLException(Util.java:220)
	at org.apache.derby.impl.jdbc.EmbedConnection.newSQLException(EmbedConnection.java:3208)
	at org.apache.derby.impl.jdbc.EmbedConnection.handleDBNotFound(EmbedConnection.java:767)
	at org.apache.derby.impl.jdbc.EmbedConnection.<init>(EmbedConnection.java:437)
	at org.apache.derby.iapi.jdbc.InternalDriver.getNewEmbedConnection(InternalDriver.java:630)
	at org.apache.derby.iapi.jdbc.InternalDriver$LoginCallable.call(InternalDriver.java:400)
	at org.apache.derby.iapi.jdbc.InternalDriver$LoginCallable.call(InternalDriver.java:376)
	at java.base/java.util.concurrent.FutureTask.run(FutureTask.java:317)
	at java.base/java.util.concurrent.ThreadPoolExecutor.runWorker(ThreadPoolExecutor.java:1144)
	at java.base/java.util.concurrent.ThreadPoolExecutor$Worker.run(ThreadPoolExecutor.java:642)
	at java.base/java.lang.Thread.run(Thread.java:1583)
============= end nested exception, level (1) ===========
Cleanup action completed
Wed Oct 16 13:12:25 EEST 2024 Thread[#42,Thread-3,5,main] Cleanup action starting
java.sql.SQLException: Database 'D:/RealDBAPI' not found.
	at org.apache.derby.impl.jdbc.SQLExceptionFactory.getSQLException(SQLExceptionFactory.java:115)
	at org.apache.derby.impl.jdbc.SQLExceptionFactory.getSQLException(SQLExceptionFactory.java:141)
	at org.apache.derby.impl.jdbc.Util.generateCsSQLException(Util.java:225)
	at org.apache.derby.impl.jdbc.Util.generateCsSQLException(Util.java:220)
	at org.apache.derby.impl.jdbc.EmbedConnection.newSQLException(EmbedConnection.java:3208)
	at org.apache.derby.impl.jdbc.EmbedConnection.handleDBNotFound(EmbedConnection.java:767)
	at org.apache.derby.impl.jdbc.EmbedConnection.<init>(EmbedConnection.java:437)
	at org.apache.derby.iapi.jdbc.InternalDriver.getNewEmbedConnection(InternalDriver.java:630)
	at org.apache.derby.iapi.jdbc.InternalDriver$LoginCallable.call(InternalDriver.java:400)
	at org.apache.derby.iapi.jdbc.InternalDriver$LoginCallable.call(InternalDriver.java:376)
	at java.base/java.util.concurrent.FutureTask.run(FutureTask.java:317)
	at java.base/java.util.concurrent.ThreadPoolExecutor.runWorker(ThreadPoolExecutor.java:1144)
	at java.base/java.util.concurrent.ThreadPoolExecutor$Worker.run(ThreadPoolExecutor.java:642)
	at java.base/java.lang.Thread.run(Thread.java:1583)
Caused by: ERROR XJ004: Database 'D:/RealDBAPI' not found.
	at org.apache.derby.shared.common.error.StandardException.newException(StandardException.java:299)
	at org.apache.derby.impl.jdbc.SQLExceptionFactory.wrapArgsForTransportAcrossDRDA(SQLExceptionFactory.java:170)
	at org.apache.derby.impl.jdbc.SQLExceptionFactory.getSQLException(SQLExceptionFactory.java:75)
	... 13 more
============= begin nested exception, level (1) ===========
ERROR XJ004: Database 'D:/RealDBAPI' not found.
	at org.apache.derby.shared.common.error.StandardException.newException(StandardException.java:299)
	at org.apache.derby.impl.jdbc.SQLExceptionFactory.wrapArgsForTransportAcrossDRDA(SQLExceptionFactory.java:170)
	at org.apache.derby.impl.jdbc.SQLExceptionFactory.getSQLException(SQLExceptionFactory.java:75)
	at org.apache.derby.impl.jdbc.SQLExceptionFactory.getSQLException(SQLExceptionFactory.java:141)
	at org.apache.derby.impl.jdbc.Util.generateCsSQLException(Util.java:225)
	at org.apache.derby.impl.jdbc.Util.generateCsSQLException(Util.java:220)
	at org.apache.derby.impl.jdbc.EmbedConnection.newSQLException(EmbedConnection.java:3208)
	at org.apache.derby.impl.jdbc.EmbedConnection.handleDBNotFound(EmbedConnection.java:767)
	at org.apache.derby.impl.jdbc.EmbedConnection.<init>(EmbedConnection.java:437)
	at org.apache.derby.iapi.jdbc.InternalDriver.getNewEmbedConnection(InternalDriver.java:630)
	at org.apache.derby.iapi.jdbc.InternalDriver$LoginCallable.call(InternalDriver.java:400)
	at org.apache.derby.iapi.jdbc.InternalDriver$LoginCallable.call(InternalDriver.java:376)
	at java.base/java.util.concurrent.FutureTask.run(FutureTask.java:317)
	at java.base/java.util.concurrent.ThreadPoolExecutor.runWorker(ThreadPoolExecutor.java:1144)
	at java.base/java.util.concurrent.ThreadPoolExecutor$Worker.run(ThreadPoolExecutor.java:642)
	at java.base/java.lang.Thread.run(Thread.java:1583)
============= end nested exception, level (1) ===========
Cleanup action completed
----------------------------------------------------------------
Wed Oct 16 13:13:00 EEST 2024:
Booting Derby version The Apache Software Foundation - Apache Derby - 10.16.1.1 - (1901046): instance a816c00e-0192-94d0-797f-000002bfe638 
on database directory D:\RealDB with class loader jdk.internal.loader.ClassLoaders$AppClassLoader@3fee733d 
Loaded from file:/C:/Users/%d0%9f%d0%9e%d0%96%d0%90%d0%a0%d0%9f%d0%a0%d0%9e%d0%a2%d0%95%d0%9a%d0%a2/.m2/repository/org/apache/derby/derby/10.16.1.1/derby-10.16.1.1.jar
java.vendor=Oracle Corporation
java.runtime.version=21+35-2513
user.dir=D:\PojarprotektAPI
os.name=Windows 10
os.arch=amd64
os.version=10.0
derby.system.home=null
Database Class Loader started - derby.database.classpath=''
